Workbook

Sheet MOSTRUARIO
A1: CS-LOJA | B1: SKU | C1: EQUIPAMENTO | D1: TECNOLOGIA | E1: BTUS | F1: TUBULAÇÃO | G1: MODELO | H1: MARCA | I1: A VISTA | J1: 30D/3X | K1: 30-60-90/6X | L1: 10X CARTAO | N1: Estoque Entrada | P1: Estoque Saída
A2: =PRODUTOS!A2 -> 26482 | B2: =PRODUTOS!B2 -> GWC09ACA-D6DNAIA/O | G2: =PRODUTOS!C2 -> DIAMOND BLACK WIFI | H2: =PRODUTOS!D2 -> GREE | I2: =IF(SAIDA!F2="",SAIDA!B2,SAIDA!F2) -> 2820 | J2: =IF(SAIDA!F2="",SAIDA!C2,SAIDA!J2) -> 3030.16 | K2: =IF(SAIDA!F2="",SAIDA!D2,SAIDA!K2) -> 3138.6 | L2: =IF(SAIDA!F2="",SAIDA!E2,SAIDA!L2) -> 3401.14
A3: =PRODUTOS!A3 -> 26483 | B3: =PRODUTOS!B3 -> GWC09ACA-D6DNAIA/I | G3: =PRODUTOS!C3 -> TIPO BARRIL | H3: =PRODUTOS!D3 -> GREE | I3: =IF(SAIDA!F3="",SAIDA!B3,SAIDA!F3) | J3: =IF(SAIDA!F3="",SAIDA!C3,SAIDA!J3) | K3: =IF(SAIDA!F3="",SAIDA!D3,SAIDA!K3) | L3: =IF(SAIDA!F3="",SAIDA!E3,SAIDA!L3)
A4: =PRODUTOS!A4 -> 26080 | B4: =PRODUTOS!B4 -> GWC12ACC-D6DNAIA/O | G4: =PRODUTOS!C4 -> DIAMOND BLACK WIFI | H4: =PRODUTOS!D4 -> GREE | I4: =IF(SAIDA!F4="",SAIDA!B4,SAIDA!F4) -> 3270 | J4: =IF(SAIDA!F4="",SAIDA!C4,SAIDA!J4) -> 3513.52 | K4: =IF(SAIDA!F4="",SAIDA!D4,SAIDA!K4) -> 3639.17 | L4: =IF(SAIDA!F4="",SAIDA!E4,SAIDA!L4) -> 3943.33
A5: =PRODUTOS!A5 -> 26081 | B5: =PRODUTOS!B5 -> GWC12ACC-D6DNAIA/I | G5: =PRODUTOS!C5 -> TIPO BARRIL | H5: =PRODUTOS!D5 -> GREE | I5: =IF(SAIDA!F5="",SAIDA!B5,SAIDA!F5) | J5: =IF(SAIDA!F5="",SAIDA!C5,SAIDA!J5) | K5: =IF(SAIDA!F5="",SAIDA!D5,SAIDA!K5) | L5: =IF(SAIDA!F5="",SAIDA!E5,SAIDA!L5)
A6: =PRODUTOS!A6 -> 26471 | B6: =PRODUTOS!B6 -> GWC18ACD-D6NNA1D | G6: =PRODUTOS!C6 -> DIAMOND BLACK WIFI | H6: =PRODUTOS!D6 -> GREE | I6: =IF(SAIDA!F6="",SAIDA!B6,SAIDA!F6) -> 4587 | J6: =IF(SAIDA!F6="",SAIDA!C6,SAIDA!J6) -> 4931.74 | K6: =IF(SAIDA!F6="",SAIDA!D6,SAIDA!K6) -> 5109.79 | L6: =IF(SAIDA!F6="",SAIDA!E6,SAIDA!L6) -> 5541.29
A7: =PRODUTOS!A7 -> 26472 | B7: =PRODUTOS!B7 -> GWC18ACD-D6NNA1D | G7: =PRODUTOS!C7 -> TIPO BARRIL | H7: =PRODUTOS!D7 -> GREE | I7: =IF(SAIDA!F7="",SAIDA!B7,SAIDA!F7) | J7: =IF(SAIDA!F7="",SAIDA!C7,SAIDA!J7) | K7: =IF(SAIDA!F7="",SAIDA!D7,SAIDA!K7) | L7: =IF(SAIDA!F7="",SAIDA!E7,SAIDA!L7)
A8: =PRODUTOS!A8 -> 26821 | B8: =PRODUTOS!B8 -> GWC12AWCXB-D6DNA4C/O | G8: =PRODUTOS!C8 -> G-SIDE FRIO - HORIZONTAL CLASSE A | H8: =PRODUTOS!D8 -> GREE | I8: =IF(SAIDA!F8="",SAIDA!B8,SAIDA!F8) -> 2645 | J8: =IF(SAIDA!F8="",SAIDA!C8,SAIDA!J8) -> 2837.75 | K8: =IF(SAIDA!F8="",SAIDA!D8,SAIDA!K8) -> 2936.99 | L8: =IF(SAIDA!F8="",SAIDA!E8,SAIDA!L8) -> 3176.58
A9: =PRODUTOS!A9 -> 27124 | B9: =PRODUTOS!B9 -> GWC12ATCXB-D6DNA3C/I | G9: =PRODUTOS!C9 -> GAS-R32 | H9: =PRODUTOS!D9 -> GREE | I9: =IF(SAIDA!F9="",SAIDA!B9,SAIDA!F9) | J9: =IF(SAIDA!F9="",SAIDA!C9,SAIDA!J9) | K9: =IF(SAIDA!F9="",SAIDA!D9,SAIDA!K9) | L9: =IF(SAIDA!F9="",SAIDA!E9,SAIDA!L9)
A10: =PRODUTOS!A10 -> 25812 | B10: =PRODUTOS!B10 -> GWC09ATB-D6DNA1 A/O | G10: =PRODUTOS!C10 -> G-TOP AUTO CONNECTION | H10: =PRODUTOS!D10 -> GREE | I10: =IF(SAIDA!F10="",SAIDA!B10,SAIDA!F10) -> 2045 | J10: =IF(SAIDA!F10="",SAIDA!C10,SAIDA!J10) -> 2178.04 | K10: =IF(SAIDA!F10="",SAIDA!D10,SAIDA!K10) -> 2245.77 | L10: =IF(SAIDA!F10="",SAIDA!E10,SAIDA!L10) -> 2407.25
A11: =PRODUTOS!A11 -> 25808 | B11: =PRODUTOS!B11 -> GWC09ATB-D6DNA1 A/I | G11: =PRODUTOS!C11 -> R-32 CONDENASADOR BARRIL | H11: =PRODUTOS!D11 -> GREE | I11: =IF(SAIDA!F11="",SAIDA!B11,SAIDA!F11) | J11: =IF(SAIDA!F11="",SAIDA!C11,SAIDA!J11) | K11: =IF(SAIDA!F11="",SAIDA!D11,SAIDA!K11) | L11: =IF(SAIDA!F11="",SAIDA!E11,SAIDA!L11)
A12: =PRODUTOS!A12 -> 25595 | B12: =PRODUTOS!B12 -> GWC18ATD-D6DNA1 A/O | G12: =PRODUTOS!C12 -> G-TOP AUTO CONNECTION | H12: =PRODUTOS!D12 -> GREE | I12: =IF(SAIDA!F12="",SAIDA!B12,SAIDA!F12) -> 3615 | J12: =IF(SAIDA!F12="",SAIDA!C12,SAIDA!J12) -> 3860.25 | K12: =IF(SAIDA!F12="",SAIDA!D12,SAIDA!K12) -> 3985.62 | L12: =IF(SAIDA!F12="",SAIDA!E12,SAIDA!L12) -> 4285.82
A13: =PRODUTOS!A13 -> 25594 | B13: =PRODUTOS!B13 -> GWC18ATD-D6DNA1 A/I | G13: =PRODUTOS!C13 -> R-32 CONDENASADOR BARRIL | H13: =PRODUTOS!D13 -> GREE | I13: =IF(SAIDA!F13="",SAIDA!B13,SAIDA!F13) | J13: =IF(SAIDA!F13="",SAIDA!C13,SAIDA!J13) | K13: =IF(SAIDA!F13="",SAIDA!D13,SAIDA!K13) | L13: =IF(SAIDA!F13="",SAIDA!E13,SAIDA!L13)
... A15: =PRODUTOS!A15 -> 25596 | B15: =PRODUTOS!B15 -> GWC24ATE-D6DNA1 A/I | G15: =PRODUTOS!C15 -> R-32 CONDENASADOR BARRIL | H15: =PRODUTOS!D15 -> GREE | I15: =IF(SAIDA!F15="",SAIDA!B15,SAIDA!F15) | J15: =IF(SAIDA!F15="",SAIDA!C15,SAIDA!J15) | K15: =IF(SAIDA!F15="",SAIDA!D15,SAIDA!K15) | L15: =IF(SAIDA!F15="",SAIDA!E15,SAIDA!L15)
A16: =PRODUTOS!A16 -> 25872 | B16: =PRODUTOS!B16 -> GWC30ATEXF-S6DNA1A/I | G16: =PRODUTOS!C16 -> G-TOP AUTO CONNECTION | H16: =PRODUTOS!D16 -> GREE | I16: =IF(SAIDA!F16="",SAIDA!B16,SAIDA!F16) -> 6758 | J16: =IF(SAIDA!F16="",SAIDA!C16,SAIDA!J16) -> 7225.54 | K16: =IF(SAIDA!F16="",SAIDA!D16,SAIDA!K16) -> 7464.99 | L16: =IF(SAIDA!F16="",SAIDA!E16,SAIDA!L16) -> 8039.63 | P16: b
A17: =PRODUTOS!A17 -> 25871 | B17: =PRODUTOS!B17 -> GWC30ATEXF-S6DNA1A/O | G17: =PRODUTOS!C17 -> R-32 CONDENASADOR HORIZONTAL | H17: =PRODUTOS!D17 -> GREE | I17: =IF(SAIDA!F17="",SAIDA!B17,SAIDA!F17) | J17: =IF(SAIDA!F17="",SAIDA!C17,SAIDA!J17) | K17: =IF(SAIDA!F17="",SAIDA!D17,SAIDA!K17) | L17: =IF(SAIDA!F17="",SAIDA!E17,SAIDA!L17)
A18: =PRODUTOS!A18 -> 25724 | B18: =PRODUTOS!B18 -> GULD36W1 | G18: =PRODUTOS!C18 -> G-PRIME COMPACTA | H18: =PRODUTOS!D18 -> GREE | I18: =IF(SAIDA!F18="",SAIDA!B18,SAIDA!F18) -> 7932 | J18: =IF(SAIDA!F18="",SAIDA!C18,SAIDA!J18) -> 8532.07 | K18: =IF(SAIDA!F18="",SAIDA!D18,SAIDA!K18) -> 8842.22 | L18: =IF(SAIDA!F18="",SAIDA!E18,SAIDA!L18) -> 9594.44
A19: =PRODUTOS!A19 -> 25723 | B19: =PRODUTOS!B19 -> GULD36ZD1 | G19: =PRODUTOS!C19 -> R-32 CONDENASADOR HORIZONTAL | H19: =PRODUTOS!D19 -> GREE | I19: =IF(SAIDA!F19="",SAIDA!B19,SAIDA!F19) | J19: =IF(SAIDA!F19="",SAIDA!C19,SAIDA!J19) | K19: =IF(SAIDA!F19="",SAIDA!D19,SAIDA!K19) | L19: =IF(SAIDA!F19="",SAIDA!E19,SAIDA!L19)
A20: =PRODUTOS!A20 -> 25928 | B20: =PRODUTOS!B20 -> GULD56W1 | G20: =PRODUTOS!C20 -> G-PRIME COMPACTA | H20: =PRODUTOS!D20 -> GREE | I20: =IF(SAIDA!F20="",SAIDA!B20,SAIDA!F20) -> 11053 | J20: =IF(SAIDA!F20="",SAIDA!C20,SAIDA!J20) -> 11924.59 | K20: =IF(SAIDA!F20="",SAIDA!D20,SAIDA!K20) -> 12377.11 | L20: =IF(SAIDA!F20="",SAIDA!E20,SAIDA!L20) -> 13480.46
A21: =PRODUTOS!A21 -> 25927 | B21: =PRODUTOS!B21 -> GULD57ZD1 | G21: =PRODUTOS!C21 -> R-32 CONDENASADOR HORIZONTAL | H21: =PRODUTOS!D21 -> GREE | I21: =IF(SAIDA!F21="",SAIDA!B21,SAIDA!F21) | J21: =IF(SAIDA!F21="",SAIDA!C21,SAIDA!J21) | K21: =IF(SAIDA!F21="",SAIDA!D21,SAIDA!K21) | L21: =IF(SAIDA!F21="",SAIDA!E21,SAIDA!L21) | N21: a
A22: =PRODUTOS!A22 -> 27098 | B22: =PRODUTOS!B22 -> GTC56EEXK-S6DNF6A/O | G22: =PRODUTOS!C22 -> G-PRIME COMPACTA - CLASSIF. B | H22: =PRODUTOS!D22 -> GREE | I22: =IF(SAIDA!F22="",SAIDA!B22,SAIDA!F22) -> 9800 | J22: =IF(SAIDA!F22="",SAIDA!C22,SAIDA!J22) -> 0 | K22: =IF(SAIDA!F22="",SAIDA!D22,SAIDA!K22) -> 0 | L22: =IF(SAIDA!F22="",SAIDA!E22,SAIDA!L22) -> 0
A23: =PRODUTOS!A23 -> 27099 | B23: =PRODUTOS!B23 -> GTC56CCXK-S6DNA1A/I | G23: =PRODUTOS!C23 -> R-32 CONDENASADOR HORIZONTAL | H23: =PRODUTOS!D23 -> GREE | I23: =IF(SAIDA!F23="",SAIDA!B23,SAIDA!F23) | J23: =IF(SAIDA!F23="",SAIDA!C23,SAIDA!J23) | K23: =IF(SAIDA!F23="",SAIDA!D23,SAIDA!K23) | L23: =IF(SAIDA!F23="",SAIDA!E23,SAIDA!L23)
A24: =PRODUTOS!A24 -> 26882 | B24: =PRODUTOS!B24 -> GWC12ATB-D6DNA2AK/O | G24: =PRODUTOS!C24 -> CONDENSADOR GREE K-7 1 VIA - BARRIL | H24: =PRODUTOS!D24 -> GREE | I24: =IF(SAIDA!F24="",SAIDA!B24,SAIDA!F24) -> 5870 | J24: =IF(SAIDA!F24="",SAIDA!C24,SAIDA!J24) -> 0 | K24: =IF(SAIDA!F24="",SAIDA!D24,SAIDA!K24) -> 0 | L24: =IF(SAIDA!F24="",SAIDA!E24,SAIDA!L24) -> 0
A25: =PRODUTOS!A25 -> 26881 | B25: =PRODUTOS!B25 -> GKC12DA-D6DNAN1A/I | G25: =PRODUTOS!C25 -> EVAP. GREE K-7 1 VIA | H25: =PRODUTOS!D25 -> GREE | I25: =IF(SAIDA!F25="",SAIDA!B25,SAIDA!F25) | J25: =IF(SAIDA!F25="",SAIDA!C25,SAIDA!J25) | K25: =IF(SAIDA!F25="",SAIDA!D25,SAIDA!K25) | L25: =IF(SAIDA!F25="",SAIDA!E25,SAIDA!L25)
A26: =PRODUTOS!A26 -> 26834 | B26: =PRODUTOS!B26 -> TD01 | G26: =PRODUTOS!C26 -> PAINEL K-7 1 VIA | H26: =PRODUTOS!D26 -> GREE | I26: =IF(SAIDA!F26="",SAIDA!B26,SAIDA!F26) | J26: =IF(SAIDA!F26="",SAIDA!C26,SAIDA!J26) | K26: =IF(SAIDA!F26="",SAIDA!D26,SAIDA!K26) | L26: =IF(SAIDA!F26="",SAIDA!E26,SAIDA!L26)
A27: =PRODUTOS!A27 -> 26890 | B27: =PRODUTOS!B27 -> GWC18ATB-D6DNA2AK/O | G27: =PRODUTOS!C27 -> CONDENSADOR GREE K-7 1 VIA - BARRIL | H27: =PRODUTOS!D27 -> GREE | I27: =IF(SAIDA!F27="",SAIDA!B27,SAIDA!F27) -> 6235 | J27: =IF(SAIDA!F27="",SAIDA!C27,SAIDA!J27) -> 0 | K27: =IF(SAIDA!F27="",SAIDA!D27,SAIDA!K27) -> 0 | L27: =IF(SAIDA!F27="",SAIDA!E27,SAIDA!L27) -> 0
A28: =PRODUTOS!A28 -> 26891 | B28: =PRODUTOS!B28 -> GKC18DA-D6DNAN1A/I | G28: =PRODUTOS!C28 -> EVAP. GREE K-7 1 VIA | H28: =PRODUTOS!D28 -> GREE | I28: =IF(SAIDA!F28="",SAIDA!B28,SAIDA!F28) | J28: =IF(SAIDA!F28="",SAIDA!C28,SAIDA!J28) | K28: =IF(SAIDA!F28="",SAIDA!D28,SAIDA!K28) | L28: =IF(SAIDA!F28="",SAIDA!E28,SAIDA!L28)
A29: =PRODUTOS!A29 -> 26834 | B29: =PRODUTOS!B29 -> TD01 | G29: =PRODUTOS!C29 -> PAINEL K-7 1 VIA | H29: =PRODUTOS!D29 -> GREE | I29: =IF(SAIDA!F29="",SAIDA!B29,SAIDA!F29) | J29: =IF(SAIDA!F29="",SAIDA!C29,SAIDA!J29) | K29: =IF(SAIDA!F29="",SAIDA!D29,SAIDA!K29) | L29: =IF(SAIDA!F29="",SAIDA!E29,SAIDA!L29)
A30: =PRODUTOS!A30 -> 26892 | B30: =PRODUTOS!B30 -> GWC24ATB-D6DNA2AK/O | G30: =PRODUTOS!C30 -> CONDENSADOR GREE K-7 1 VIA - BARRIL | H30: =PRODUTOS!D30 -> GREE | I30: =IF(SAIDA!F30="",SAIDA!B30,SAIDA!F30) -> 7450 | J30: =IF(SAIDA!F30="",SAIDA!C30,SAIDA!J30) -> 0 | K30: =IF(SAIDA!F30="",SAIDA!D30,SAIDA!K30) -> 0 | L30: =IF(SAIDA!F30="",SAIDA!E30,SAIDA!L30) -> 0
A31: =PRODUTOS!A31 -> 26893 | B31: =PRODUTOS!B31 -> GKC24DA-D6DNAN1A/I | G31: =PRODUTOS!C31 -> EVAP. GREE K-7 1 VIA | H31: =PRODUTOS!D31 -> GREE | I31: =IF(SAIDA!F31="",SAIDA!B31,SAIDA!F31) | J31: =IF(SAIDA!F31="",SAIDA!C31,SAIDA!J31) | K31: =IF(SAIDA!F31="",SAIDA!D31,SAIDA!K31) | L31: =IF(SAIDA!F31="",SAIDA!E31,SAIDA!L31)
A32: =PRODUTOS!A32 -> 26834 | B32: =PRODUTOS!B32 -> TD01 | G32: =PRODUTOS!C32 -> PAINEL K-7 1 VIA | H32: =PRODUTOS!D32 -> GREE | I32: =IF(SAIDA!F32="",SAIDA!B32,SAIDA!F32) | J32: =IF(SAIDA!F32="",SAIDA!C32,SAIDA!J32) | K32: =IF(SAIDA!F32="",SAIDA!D32,SAIDA!K32) | L32: =IF(SAIDA!F32="",SAIDA!E32,SAIDA!L32)
A33: =PRODUTOS!A33 -> 25721 | B33: =PRODUTOS!B33 -> GULD24W1 | G33: =PRODUTOS!C33 -> G-PRIME PLUS - HORIZONTAL | H33: =PRODUTOS!D33 -> GREE | I33: =IF(SAIDA!F33="",SAIDA!B33,SAIDA!F33) -> 7123 | J33: =IF(SAIDA!F33="",SAIDA!C33,SAIDA!J33) -> 7732.4 | K33: =IF(SAIDA!F33="",SAIDA!D33,SAIDA!K33) -> 8051.79 | L33: =IF(SAIDA!F33="",SAIDA!E33,SAIDA!L33) -> 8839.26
... A250: =PRODUTOS!A250 -> 0 | B250: =PRODUTOS!B250 -> 0 | G250: =PRODUTOS!C250 -> 0 | H250: =PRODUTOS!D250 -> 0 | I250: =IF(SAIDA!F250="",SAIDA!B250,SAIDA!F250) | J250: =IF(SAIDA!F250="",SAIDA!C250,SAIDA!J250) | K250: =IF(SAIDA!F250="",SAIDA!D250,SAIDA!K250) | L250: =IF(SAIDA!F250="",SAIDA!E250,SAIDA!L250)
A251: .

Sheet PARAMETROS
A1: Nome | B1: Valor | C1: Significado | D1: Fonte da decisão
A2: ICMS_VENDA | B2: 0.19 | C2: ICMS interno de venda (PA, 19%) | D2: Contabilidade - 18/08/2026
A3: ICMS_CREDITO | B3: 0.12 | C3: Crédito ICMS na compra (interestadual) | D3: Contabilidade – 18/08/2026
A4: PIS | B4: 0.0065 | C4: PIS — Lucro Presumido cumulativo | D4: Contabilidade - 18/08/2026
A5: COFINS | B5: 0.03 | C5: COFINS — Lucro Presumido cumulativo | D5: Contabilidade - 18/08/2026
A6: IRPJ | B6: 0.0211 | C6: IRPJ — presunção | D6: Contabilidade - 18/08/2026
A7: CSLL | B7: 0.0117 | C7: CSLL — presunção | D7: Contabilidade - 18/08/2026
A8: TRIBUTOS | B8: =SUM(B4:B7) -> 0.0693 | C8: Soma PIS+COFINS+IRPJ+CSLL | D8: Forma soma
A9: IMPOSTOS | B9: =B2+B8 -> 0.2593 | C9: ICMS + federais | D9: Forma soma
A10: TAXA_3X | B10: 0.044 | C10: Taxa/juros 3x | D10: Escada atual - 18/08/2026
A11: TAXA_6X | B11: 0.0644 | C11: Taxa/juros 6x | D11: Escada atual – 18/08/2026
A12: TAXA_10X | B12: 0.1084 | C12: Taxa/juros 10x | D12: Escada atual – 18/08/2026
A13: MARGEM_PADRAO | B13: 0.3 | C13: Margem alvo default | D13: Decisão de negócio - ?
A14: FRETE | B14: 0 | C14: Fator de frete (pendência) | D14: Em aberto - ?
A15: IPI | B15: 0 | C15: Fator de IPI (pendência) | D15: Em aberto - ?
A20: Sempre coloque os valores em numeros decimais para representar a porcentagem. Exemplo: 10% = 0,1

Sheet PRODUTOS
A1: CS-LOJA | B1: SKU | C1: MODELO | D1: MARCA | E1: CUSTO_NF | F1: MARGEM_ALVO
A2: 26482 | B2: GWC09ACA-D6DNAIA/O | C2: DIAMOND BLACK WIFI | D2: GREE | E2: 2033 | F2: 0.3 | H2: Os produtos são catalogados aqui. Estes campos são utilizados automaticamente na planilha mais à frente. CUSTO_NF tem seu crédito ICMS feito posteriormente, então coloque o preço da fábrica. A MARGEM_ALVO sobrepõe a MARGEM_PADRAO da loja para aquele produto.
A3: 26483 | B3: GWC09ACA-D6DNAIA/I | C3: TIPO BARRIL | D3: GREE | F3: 0.3
A4: 26080 | B4: GWC12ACC-D6DNAIA/O | C4: DIAMOND BLACK WIFI | D4: GREE | E4: 2359 | F4: 0.3
A5: 26081 | B5: GWC12ACC-D6DNAIA/I | C5: TIPO BARRIL | D5: GREE | F5: 0.3
A6: 26471 | B6: GWC18ACD-D6NNA1D | C6: DIAMOND BLACK WIFI | D6: GREE | E6: 3281 | F6: 0.3
A7: 26472 | B7: GWC18ACD-D6NNA1D | C7: TIPO BARRIL | D7: GREE | F7: 0.3
A8: 26821 | B8: GWC12AWCXB-D6DNA4C/O | C8: G-SIDE FRIO - HORIZONTAL CLASSE A | D8: GREE | E8: 1947 | F8: 0.3
A9: 27124 | B9: GWC12ATCXB-D6DNA3C/I | C9: GAS-R32 | D9: GREE | F9: 0.3
A10: 25812 | B10: GWC09ATB-D6DNA1 A/O | C10: G-TOP AUTO CONNECTION | D10: GREE | E10: 1674 | F10: 0.3
A11: 25808 | B11: GWC09ATB-D6DNA1 A/I | C11: R-32 CONDENASADOR BARRIL | D11: GREE | F11: 0.3
A12: 25595 | B12: GWC18ATD-D6DNA1 A/O | C12: G-TOP AUTO CONNECTION | D12: GREE | E12: 2845 | F12: 0.3
A13: 25594 | B13: GWC18ATD-D6DNA1 A/I | C13: R-32 CONDENASADOR BARRIL | D13: GREE | F13: 0.3
A14: 25597 | B14: GWC24ATE-D6DNA1 A/O | C14: G-TOP AUTO CONNECTION | D14: GREE | E14: 3596 | F14: 0.3
A15: 25596 | B15: GWC24ATE-D6DNA1 A/I | C15: R-32 CONDENASADOR BARRIL | D15: GREE | F15: 0.3
A16: 25872 | B16: GWC30ATEXF-S6DNA1A/I | C16: G-TOP AUTO CONNECTION | D16: GREE | E16: 5222 | F16: 0.3
A17: 25871 | B17: GWC30ATEXF-S6DNA1A/O | C17: R-32 CONDENASADOR HORIZONTAL | D17: GREE | F17: 0.3
A18: 25724 | B18: GULD36W1 | C18: G-PRIME COMPACTA | D18: GREE | E18: 5639 | F18: 0.3
A19: 25723 | B19: GULD36ZD1 | C19: R-32 CONDENASADOR HORIZONTAL | D19: GREE | F19: 0.3
A20: 25928 | B20: GULD56W1 | C20: G-PRIME COMPACTA | D20: GREE | E20: 7561 | F20: 0.3
A21: 25927 | B21: GULD57ZD1 | C21: R-32 CONDENASADOR HORIZONTAL | D21: GREE | F21: 0.3
A22: 27098 | B22: GTC56EEXK-S6DNF6A/O | C22: G-PRIME COMPACTA - CLASSIF. B | D22: GREE | E22: 0 | F22: 0.3
A23: 27099 | B23: GTC56CCXK-S6DNA1A/I | C23: R-32 CONDENASADOR HORIZONTAL | D23: GREE | F23: 0.3
A24: 26882 | B24: GWC12ATB-D6DNA2AK/O | C24: CONDENSADOR GREE K-7 1 VIA - BARRIL | D24: GREE | E24: 0 | F24: 0.3
A25: 26881 | B25: GKC12DA-D6DNAN1A/I | C25: EVAP. GREE K-7 1 VIA | D25: GREE | F25: 0.3
A26: 26834 | B26: TD01 | C26: PAINEL K-7 1 VIA | D26: GREE | F26: 0.3
A27: 26890 | B27: GWC18ATB-D6DNA2AK/O | C27: CONDENSADOR GREE K-7 1 VIA - BARRIL | D27: GREE | E27: 0 | F27: 0.3
A28: 26891 | B28: GKC18DA-D6DNAN1A/I | C28: EVAP. GREE K-7 1 VIA | D28: GREE | F28: 0.3
A29: 26834 | B29: TD01 | C29: PAINEL K-7 1 VIA | D29: GREE | F29: 0.3
A30: 26892 | B30: GWC24ATB-D6DNA2AK/O | C30: CONDENSADOR GREE K-7 1 VIA - BARRIL | D30: GREE | E30: 0 | F30: 0.3
A31: 26893 | B31: GKC24DA-D6DNAN1A/I | C31: EVAP. GREE K-7 1 VIA | D31: GREE | F31: 0.3
A32: 26834 | B32: TD01 | C32: PAINEL K-7 1 VIA | D32: GREE | F32: 0.3
A33: 25721 | B33: GULD24W1 | C33: G-PRIME PLUS - HORIZONTAL | D33: GREE | E33: 4519 | F33: 0.3
A34: 25720 | B34: GULD24T1 | C34: R-32 | D34: GREE | F34: 0.3
A35: 25722 | B35: TF06/24 (TL10000220) | D35: GREE | F35: 0.3
A36: 25937 | B36: GULD24W1 | C36: G-PRIME COMPACTA - HORIZONTAL | D36: GREE | E36: 4519 | F36: 0.3
A37: 25936 | B37: GULD24T1 | C37: R-32 | D37: GREE | F37: 0.3
A38: 25938 | B38: TF06 /24 (TL10000220) | D38: GREE | F38: 0.3
A39: 25930 | B39: GULD36W1 | C39: G-PRIME COMPACTA - HORIZONTAL | D39: GREE | E39: 6981 | F39: 0.3
A40: 25929 | B40: GULD36T1 | C40: R-32 | D40: GREE | F40: 0.3
...

Sheet CALCULO
A1: CS-LOJA | B1: CUSTO_LIQ | C1: MARGEM_USADA | D1: AVISTA | E1: 3X | F1: 6X | G1: 10X
A2: =PRODUTOS!A2 -> 26482 | B2: =IF(PRODUTOS!E2="","",PRODUTOS!E2*(1-ICMS_CREDITO)) -> 1789.04 | C2: =IF(PRODUTOS!F2="",MARGEM_PADRAO,PRODUTOS!F2) -> 0.3 | D2: =IF(B2="","",ROUND(B2/(1-IMPOSTOS-C2),2)) -> 4059.54 | E2: =IF(B2="","",ROUND(B2/(1-IMPOSTOS-C2-TAXA_3X),2)) -> 4509.81 | F2: =IF(B2="","",ROUND(B2/(1-IMPOSTOS-C2-TAXA_6X),2)) -> 4754.29 | G2: =IF(B2="","",ROUND(B2/(1-IMPOSTOS-C2-TAXA_10X),2)) -> 5383.81 | I2: Todas as células aqui presentes são calculadas automaticamente com as informações obtidas pelas outras páginas da planilha, então ela é bloqueada para mudanças por padrão.
A3: =PRODUTOS!A3 -> 26483 | B3: =IF(PRODUTOS!E3="","",PRODUTOS!E3*(1-ICMS_CREDITO)) | C3: =IF(PRODUTOS!F3="",MARGEM_PADRAO,PRODUTOS!F3) -> 0.3 | D3: =IF(B3="","",ROUND(B3/(1-IMPOSTOS-C3),2)) | E3: =IF(B3="","",ROUND(B3/(1-IMPOSTOS-C3-TAXA_3X),2)) | F3: =IF(B3="","",ROUND(B3/(1-IMPOSTOS-C3-TAXA_6X),2)) | G3: =IF(B3="","",ROUND(B3/(1-IMPOSTOS-C3-TAXA_10X),2))
A4: =PRODUTOS!A4 -> 26080 | B4: =IF(PRODUTOS!E4="","",PRODUTOS!E4*(1-ICMS_CREDITO)) -> 2075.92 | C4: =IF(PRODUTOS!F4="",MARGEM_PADRAO,PRODUTOS!F4) -> 0.3 | D4: =IF(B4="","",ROUND(B4/(1-IMPOSTOS-C4),2)) -> 4710.51 | E4: =IF(B4="","",ROUND(B4/(1-IMPOSTOS-C4-TAXA_3X),2)) -> 5232.97 | F4: =IF(B4="","",ROUND(B4/(1-IMPOSTOS-C4-TAXA_6X),2)) -> 5516.66 | G4: =IF(B4="","",ROUND(B4/(1-IMPOSTOS-C4-TAXA_10X),2)) -> 6247.13
A5: =PRODUTOS!A5 -> 26081 | B5: =IF(PRODUTOS!E5="","",PRODUTOS!E5*(1-ICMS_CREDITO)) | C5: =IF(PRODUTOS!F5="",MARGEM_PADRAO,PRODUTOS!F5) -> 0.3 | D5: =IF(B5="","",ROUND(B5/(1-IMPOSTOS-C5),2)) | E5: =IF(B5="","",ROUND(B5/(1-IMPOSTOS-C5-TAXA_3X),2)) | F5: =IF(B5="","",ROUND(B5/(1-IMPOSTOS-C5-TAXA_6X),2)) | G5: =IF(B5="","",ROUND(B5/(1-IMPOSTOS-C5-TAXA_10X),2))
A6: =PRODUTOS!A6 -> 26471 | B6: =IF(PRODUTOS!E6="","",PRODUTOS!E6*(1-ICMS_CREDITO)) -> 2887.28 | C6: =IF(PRODUTOS!F6="",MARGEM_PADRAO,PRODUTOS!F6) -> 0.3 | D6: =IF(B6="","",ROUND(B6/(1-IMPOSTOS-C6),2)) -> 6551.58 | E6: =IF(B6="","",ROUND(B6/(1-IMPOSTOS-C6-TAXA_3X),2)) -> 7278.25 | F6: =IF(B6="","",ROUND(B6/(1-IMPOSTOS-C6-TAXA_6X),2)) -> 7672.81 | G6: =IF(B6="","",ROUND(B6/(1-IMPOSTOS-C6-TAXA_10X),2)) -> 8688.78
A7: =PRODUTOS!A7 -> 26472 | B7: =IF(PRODUTOS!E7="","",PRODUTOS!E7*(1-ICMS_CREDITO)) | C7: =IF(PRODUTOS!F7="",MARGEM_PADRAO,PRODUTOS!F7) -> 0.3 | D7: =IF(B7="","",ROUND(B7/(1-IMPOSTOS-C7),2)) | E7: =IF(B7="","",ROUND(B7/(1-IMPOSTOS-C7-TAXA_3X),2)) | F7: =IF(B7="","",ROUND(B7/(1-IMPOSTOS-C7-TAXA_6X),2)) | G7: =IF(B7="","",ROUND(B7/(1-IMPOSTOS-C7-TAXA_10X),2))
A8: =PRODUTOS!A8 -> 26821 | B8: =IF(PRODUTOS!E8="","",PRODUTOS!E8*(1-ICMS_CREDITO)) -> 1713.36 | C8: =IF(PRODUTOS!F8="",MARGEM_PADRAO,PRODUTOS!F8) -> 0.3 | D8: =IF(B8="","",ROUND(B8/(1-IMPOSTOS-C8),2)) -> 3887.81 | E8: =IF(B8="","",ROUND(B8/(1-IMPOSTOS-C8-TAXA_3X),2)) -> 4319.03 | F8: =IF(B8="","",ROUND(B8/(1-IMPOSTOS-C8-TAXA_6X),2)) -> 4553.18 | G8: =IF(B8="","",ROUND(B8/(1-IMPOSTOS-C8-TAXA_10X),2)) -> 5156.06
A9: =PRODUTOS!A9 -> 27124 | B9: =IF(PRODUTOS!E9="","",PRODUTOS!E9*(1-ICMS_CREDITO)) | C9: =IF(PRODUTOS!F9="",MARGEM_PADRAO,PRODUTOS!F9) -> 0.3 | D9: =IF(B9="","",ROUND(B9/(1-IMPOSTOS-C9),2)) | E9: =IF(B9="","",ROUND(B9/(1-IMPOSTOS-C9-TAXA_3X),2)) | F9: =IF(B9="","",ROUND(B9/(1-IMPOSTOS-C9-TAXA_6X),2)) | G9: =IF(B9="","",ROUND(B9/(1-IMPOSTOS-C9-TAXA_10X),2))
A10: =PRODUTOS!A10 -> 25812 | B10: =IF(PRODUTOS!E10="","",PRODUTOS!E10*(1-ICMS_CREDITO)) -> 1473.12 | C10: =IF(PRODUTOS!F10="",MARGEM_PADRAO,PRODUTOS!F10) -> 0.3 | D10: =IF(B10="","",ROUND(B10/(1-IMPOSTOS-C10),2)) -> 3342.68 | E10: =IF(B10="","",ROUND(B10/(1-IMPOSTOS-C10-TAXA_3X),2)) -> 3713.44 | F10: =IF(B10="","",ROUND(B10/(1-IMPOSTOS-C10-TAXA_6X),2)) -> 3914.75 | G10: =IF(B10="","",ROUND(B10/(1-IMPOSTOS-C10-TAXA_10X),2)) -> 4433.1
A11: =PRODUTOS!A11 -> 25808 | B11: =IF(PRODUTOS!E11="","",PRODUTOS!E11*(1-ICMS_CREDITO)) | C11: =IF(PRODUTOS!F11="",MARGEM_PADRAO,PRODUTOS!F11) -> 0.3 | D11: =IF(B11="","",ROUND(B11/(1-IMPOSTOS-C11),2)) | E11: =IF(B11="","",ROUND(B11/(1-IMPOSTOS-C11-TAXA_3X),2)) | F11: =IF(B11="","",ROUND(B11/(1-IMPOSTOS-C11-TAXA_6X),2)) | G11: =IF(B11="","",ROUND(B11/(1-IMPOSTOS-C11-TAXA_10X),2))
A12: =PRODUTOS!A12 -> 25595 | B12: =IF(PRODUTOS!E12="","",PRODUTOS!E12*(1-ICMS_CREDITO)) -> 2503.6 | C12: =IF(PRODUTOS!F12="",MARGEM_PADRAO,PRODUTOS!F12) -> 0.3 | D12: =IF(B12="","",ROUND(B12/(1-IMPOSTOS-C12),2)) -> 5680.96 | E12: =IF(B12="","",ROUND(B12/(1-IMPOSTOS-C12-TAXA_3X),2)) -> 6311.07 | F12: =IF(B12="","",ROUND(B12/(1-IMPOSTOS-C12-TAXA_6X),2)) -> 6653.2 | G12: =IF(B12="","",ROUND(B12/(1-IMPOSTOS-C12-TAXA_10X),2)) -> 7534.16
A13: =PRODUTOS!A13 -> 25594 | B13: =IF(PRODUTOS!E13="","",PRODUTOS!E13*(1-ICMS_CREDITO)) | C13: =IF(PRODUTOS!F13="",MARGEM_PADRAO,PRODUTOS!F13) -> 0.3 | D13: =IF(B13="","",ROUND(B13/(1-IMPOSTOS-C13),2)) | E13: =IF(B13="","",ROUND(B13/(1-IMPOSTOS-C13-TAXA_3X),2)) | F13: =IF(B13="","",ROUND(B13/(1-IMPOSTOS-C13-TAXA_6X),2)) | G13: =IF(B13="","",ROUND(B13/(1-IMPOSTOS-C13-TAXA_10X),2))
A14: =PRODUTOS!A14 -> 25597 | B14: =IF(PRODUTOS!E14="","",PRODUTOS!E14*(1-ICMS_CREDITO)) -> 3164.48 | C14: =IF(PRODUTOS!F14="",MARGEM_PADRAO,PRODUTOS!F14) -> 0.3 | D14: =IF(B14="","",ROUND(B14/(1-IMPOSTOS-C14),2)) -> 7180.58 | E14: =IF(B14="","",ROUND(B14/(1-IMPOSTOS-C14-TAXA_3X),2)) -> 7977.01 | F14: =IF(B14="","",ROUND(B14/(1-IMPOSTOS-C14-TAXA_6X),2)) -> 8409.46 | G14: =IF(B14="","",ROUND(B14/(1-IMPOSTOS-C14-TAXA_10X),2)) -> 9522.96
... A251: =PRODUTOS!A251 -> 0 | B251: =IF(PRODUTOS!E251="","",PRODUTOS!E251*(1-ICMS_CREDITO)) | C251: =IF(PRODUTOS!F251="",MARGEM_PADRAO,PRODUTOS!F251) -> 0.3 | D251: =IF(B251="","",ROUND(B251/(1-IMPOSTOS-C251),2)) | E251: =IF(B251="","",ROUND(B251/(1-IMPOSTOS-C251-TAXA_3X),2)) | F251: =IF(B251="","",ROUND(B251/(1-IMPOSTOS-C251-TAXA_6X),2)) | G251: =IF(B251="","",ROUND(B251/(1-IMPOSTOS-C251-TAXA_10X),2))

Sheet SAIDA
A1: CS-LOJA | B1: AVISTA_CALC | C1: 3X | D1: 6X | E1: 10X | F1: AVISTA_PRATICADO | G1: DESVIO% | H1: MARGEM_REAL% | I1: GAP_MARGEM% | J1: NOVO_3X | K1: NOVO_6X | L1: NOVO_10X
A2: =CALCULO!A2 -> 26482 | B2: =IF(CALCULO!D2="","",CALCULO!D2) -> 4059.54 | C2: =IF(CALCULO!E2="","",CALCULO!E2) -> 4509.81 | D2: =IF(CALCULO!F2="","",CALCULO!F2) -> 4754.29 | E2: =IF(CALCULO!G2="","",CALCULO!G2) -> 5383.81 | F2: 2820 | G2: =IF(F2="","",ROUND((F2-B2)/B2,4)) -> -0.3053 | H2: =IF(F2="","",1-IMPOSTOS-CALCULO!B2/F2) -> 0.10628865 | I2: =IF(F2="","",H2-CALCULO!C2) -> -0.19371135 | J2: =IF(F2="","",ROUND(CALCULO!B2/(1-IMPOSTOS-H2-TAXA_3X),2)) -> 3030.16 | K2: =IF(F2="","",ROUND(CALCULO!B2/(1-IMPOSTOS-H2-TAXA_6X),2)) -> 3138.6 | L2: =IF(F2="","",ROUND(CALCULO!B2/(1-IMPOSTOS-H2-TAXA_10X),2)) -> 3401.14 | N2: Somente o campo AVISTA_PRATICADO deve ser modificado, pois ele representa o valor atual dentro da disputa de preços. Observação: nem sempre é necessário ter um preço inferior ao dos adversários para vender o produto.
A3: =CALCULO!A3 -> 26483 | B3: =IF(CALCULO!D3="","",CALCULO!D3) | C3: =IF(CALCULO!E3="","",CALCULO!E3) | D3: =IF(CALCULO!F3="","",CALCULO!F3) | E3: =IF(CALCULO!G3="","",CALCULO!G3) | G3: =IF(F3="","",ROUND((F3-B3)/B3,4)) | H3: =IF(F3="","",1-IMPOSTOS-CALCULO!B3/F3) | I3: =IF(F3="","",H3-CALCULO!C3) | J3: =IF(F3="","",ROUND(CALCULO!B3/(1-IMPOSTOS-H3-TAXA_3X),2)) | K3: =IF(F3="","",ROUND(CALCULO!B3/(1-IMPOSTOS-H3-TAXA_6X),2)) | L3: =IF(F3="","",ROUND(CALCULO!B3/(1-IMPOSTOS-H3-TAXA_10X),2))
A4: =CALCULO!A4 -> 26080 | B4: =IF(CALCULO!D4="","",CALCULO!D4) -> 4710.51 | C4: =IF(CALCULO!E4="","",CALCULO!E4) -> 5232.97 | D4: =IF(CALCULO!F4="","",CALCULO!F4) -> 5516.66 | E4: =IF(CALCULO!G4="","",CALCULO!G4) -> 6247.13 | F4: 3270 | G4: =IF(F4="","",ROUND((F4-B4)/B4,4)) -> -0.3058 | H4: =IF(F4="","",1-IMPOSTOS-CALCULO!B4/F4) -> 0.10586208 | I4: =IF(F4="","",H4-CALCULO!C4) -> -0.19413792 | J4: =IF(F4="","",ROUND(CALCULO!B4/(1-IMPOSTOS-H4-TAXA_3X),2)) -> 3513.52 | K4: =IF(F4="","",ROUND(CALCULO!B4/(1-IMPOSTOS-H4-TAXA_6X),2)) -> 3639.17 | L4: =IF(F4="","",ROUND(CALCULO!B4/(1-IMPOSTOS-H4-TAXA_10X),2)) -> 3943.33
A5: =CALCULO!A5 -> 26081 | B5: =IF(CALCULO!D5="","",CALCULO!D5) | C5: =IF(CALCULO!E5="","",CALCULO!E5) | D5: =IF(CALCULO!F5="","",CALCULO!F5) | E5: =IF(CALCULO!G5="","",CALCULO!G5) | G5: =IF(F5="","",ROUND((F5-B5)/B5,4)) | H5: =IF(F5="","",1-IMPOSTOS-CALCULO!B5/F5) | I5: =IF(F5="","",H5-CALCULO!C5) | J5: =IF(F5="","",ROUND(CALCULO!B5/(1-IMPOSTOS-H5-TAXA_3X),2)) | K5: =IF(F5="","",ROUND(CALCULO!B5/(1-IMPOSTOS-H5-TAXA_6X),2)) | L5: =IF(F5="","",ROUND(CALCULO!B5/(1-IMPOSTOS-H5-TAXA_10X),2))
A6: =CALCULO!A6 -> 26471 | B6: =IF(CALCULO!D6="","",CALCULO!D6) -> 6551.58 | C6: =IF(CALCULO!E6="","",CALCULO!E6) -> 7278.25 | D6: =IF(CALCULO!F6="","",CALCULO!F6) -> 7672.81 | E6: =IF(CALCULO!G6="","",CALCULO!G6) -> 8688.78 | F6: 4587 | G6: =IF(F6="","",ROUND((F6-B6)/B6,4)) -> -0.2999 | H6: =IF(F6="","",1-IMPOSTOS-CALCULO!B6/F6) -> 0.11125156 | I6: =IF(F6="","",H6-CALCULO!C6) -> -0.18874844 | J6: =IF(F6="","",ROUND(CALCULO!B6/(1-IMPOSTOS-H6-TAXA_3X),2)) -> 4931.74 | K6: =IF(F6="","",ROUND(CALCULO!B6/(1-IMPOSTOS-H6-TAXA_6X),2)) -> 5109.79 | L6: =IF(F6="","",ROUND(CALCULO!B6/(1-IMPOSTOS-H6-TAXA_10X),2)) -> 5541.29
A7: =CALCULO!A7 -> 26472 | B7: =IF(CALCULO!D7="","",CALCULO!D7) | C7: =IF(CALCULO!E7="","",CALCULO!E7) | D7: =IF(CALCULO!F7="","",CALCULO!F7) | E7: =IF(CALCULO!G7="","",CALCULO!G7) | G7: =IF(F7="","",ROUND((F7-B7)/B7,4)) | H7: =IF(F7="","",1-IMPOSTOS-CALCULO!B7/F7) | I7: =IF(F7="","",H7-CALCULO!C7) | J7: =IF(F7="","",ROUND(CALCULO!B7/(1-IMPOSTOS-H7-TAXA_3X),2)) | K7: =IF(F7="","",ROUND(CALCULO!B7/(1-IMPOSTOS-H7-TAXA_6X),2)) | L7: =IF(F7="","",ROUND(CALCULO!B7/(1-IMPOSTOS-H7-TAXA_10X),2))
A8: =CALCULO!A8 -> 26821 | B8: =IF(CALCULO!D8="","",CALCULO!D8) -> 3887.81 | C8: =IF(CALCULO!E8="","",CALCULO!E8) -> 4319.03 | D8: =IF(CALCULO!F8="","",CALCULO!F8) -> 4553.18 | E8: =IF(CALCULO!G8="","",CALCULO!G8) -> 5156.06 | F8: 2645 | G8: =IF(F8="","",ROUND((F8-B8)/B8,4)) -> -0.3197 | H8: =IF(F8="","",1-IMPOSTOS-CALCULO!B8/F8) -> 0.092926843 | I8: =IF(F8="","",H8-CALCULO!C8) -> -0.20707316 | J8: =IF(F8="","",ROUND(CALCULO!B8/(1-IMPOSTOS-H8-TAXA_3X),2)) -> 2837.75 | K8: =IF(F8="","",ROUND(CALCULO!B8/(1-IMPOSTOS-H8-TAXA_6X),2)) -> 2936.99 | L8: =IF(F8="","",ROUND(CALCULO!B8/(1-IMPOSTOS-H8-TAXA_10X),2)) -> 3176.58
A9: =CALCULO!A9 -> 27124 | B9: =IF(CALCULO!D9="","",CALCULO!D9) | C9: =IF(CALCULO!E9="","",CALCULO!E9) | D9: =IF(CALCULO!F9="","",CALCULO!F9) | E9: =IF(CALCULO!G9="","",CALCULO!G9) | G9: =IF(F9="","",ROUND((F9-B9)/B9,4)) | H9: =IF(F9="","",1-IMPOSTOS-CALCULO!B9/F9) | I9: =IF(F9="","",H9-CALCULO!C9) | J9: =IF(F9="","",ROUND(CALCULO!B9/(1-IMPOSTOS-H9-TAXA_3X),2)) | K9: =IF(F9="","",ROUND(CALCULO!B9/(1-IMPOSTOS-H9-TAXA_6X),2)) | L9: =IF(F9="","",ROUND(CALCULO!B9/(1-IMPOSTOS-H9-TAXA_10X),2))
A10: =CALCULO!A10 -> 25812 | B10: =IF(CALCULO!D10="","",CALCULO!D10) -> 3342.68 | C10: =IF(CALCULO!E10="","",CALCULO!E10) -> 3713.44 | D10: =IF(CALCULO!F10="","",CALCULO!F10) -> 3914.75 | E10: =IF(CALCULO!G10="","",CALCULO!G10) -> 4433.1 | F10: 2045 | G10: =IF(F10="","",ROUND((F10-B10)/B10,4)) -> -0.3882 | H10: =IF(F10="","",1-IMPOSTOS-CALCULO!B10/F10) -> 0.020347922 | I10: =IF(F10="","",H10-CALCULO!C10) -> -0.27965208 | J10: =IF(F10="","",ROUND(CALCULO!B10/(1-IMPOSTOS-H10-TAXA_3X),2)) -> 2178.04 | K10: =IF(F10="","",ROUND(CALCULO!B10/(1-IMPOSTOS-H10-TAXA_6X),2)) -> 2245.77 | L10: =IF(F10="","",ROUND(CALCULO!B10/(1-IMPOSTOS-H10-TAXA_10X),2)) -> 2407.25
A11: =CALCULO!A11 -> 25808 | B11: =IF(CALCULO!D11="","",CALCULO!D11) | C11: =IF(CALCULO!E11="","",CALCULO!E11) | D11: =IF(CALCULO!F11="","",CALCULO!F11) | E11: =IF(CALCULO!G11="","",CALCULO!G11) | G11: =IF(F11="","",ROUND((F11-B11)/B11,4)) | H11: =IF(F11="","",1-IMPOSTOS-CALCULO!B11/F11) | I11: =IF(F11="","",H11-CALCULO!C11) | J11: =IF(F11="","",ROUND(CALCULO!B11/(1-IMPOSTOS-H11-TAXA_3X),2)) | K11: =IF(F11="","",ROUND(CALCULO!B11/(1-IMPOSTOS-H11-TAXA_6X),2)) | L11: =IF(F11="","",ROUND(CALCULO!B11/(1-IMPOSTOS-H11-TAXA_10X),2))
A12: =CALCULO!A12 -> 25595 | B12: =IF(CALCULO!D12="","",CALCULO!D12) -> 5680.96 | C12: =IF(CALCULO!E12="","",CALCULO!E12) -> 6311.07 | D12: =IF(CALCULO!F12="","",CALCULO!F12) -> 6653.2 | E12: =IF(CALCULO!G12="","",CALCULO!G12) -> 7534.16 | F12: 3615 | G12: =IF(F12="","",ROUND((F12-B12)/B12,4)) -> -0.3637 | H12: =IF(F12="","",1-IMPOSTOS-CALCULO!B12/F12) -> 0.048141217 | I12: =IF(F12="","",H12-CALCULO!C12) -> -0.25185878 | J12: =IF(F12="","",ROUND(CALCULO!B12/(1-IMPOSTOS-H12-TAXA_3X),2)) -> 3860.25 | K12: =IF(F12="","",ROUND(CALCULO!B12/(1-IMPOSTOS-H12-TAXA_6X),2)) -> 3985.62 | L12: =IF(F12="","",ROUND(CALCULO!B12/(1-IMPOSTOS-H12-TAXA_10X),2)) -> 4285.82 | N12: DESVIO% representa a diferença percentual do valor praticado para o calculado.
A13: =CALCULO!A13 -> 25594 | B13: =IF(CALCULO!D13="","",CALCULO!D13) | C13: =IF(CALCULO!E13="","",CALCULO!E13) | D13: =IF(CALCULO!F13="","",CALCULO!F13) | E13: =IF(CALCULO!G13="","",CALCULO!G13) | G13: =IF(F13="","",ROUND((F13-B13)/B13,4)) | H13: =IF(F13="","",1-IMPOSTOS-CALCULO!B13/F13) | I13: =IF(F13="","",H13-CALCULO!C13) | J13: =IF(F13="","",ROUND(CALCULO!B13/(1-IMPOSTOS-H13-TAXA_3X),2)) | K13: =IF(F13="","",ROUND(CALCULO!B13/(1-IMPOSTOS-H13-TAXA_6X),2)) | L13: =IF(F13="","",ROUND(CALCULO!B13/(1-IMPOSTOS-H13-TAXA_10X),2))
A14: =CALCULO!A14 -> 25597 | B14: =IF(CALCULO!D14="","",CALCULO!D14) -> 7180.58 | C14: =IF(CALCULO!E14="","",CALCULO!E14) -> 7977.01 | D14: =IF(CALCULO!F14="","",CALCULO!F14) -> 8409.46 | E14: =IF(CALCULO!G14="","",CALCULO!G14) -> 9522.96 | F14: 4890 | G14: =IF(F14="","",ROUND((F14-B14)/B14,4)) -> -0.319 | H14: =IF(F14="","",1-IMPOSTOS-CALCULO!B14/F14) -> 0.093567076 | I14: =IF(F14="","",H14-CALCULO!C14) -> -0.20643292 | J14: =IF(F14="","",ROUND(CALCULO!B14/(1-IMPOSTOS-H14-TAXA_3X),2)) -> 5246.74 | K14: =IF(F14="","",ROUND(CALCULO!B14/(1-IMPOSTOS-H14-TAXA_6X),2)) -> 5430.41 | L14: =IF(F14="","",ROUND(CALCULO!B14/(1-IMPOSTOS-H14-TAXA_10X),2)) -> 5873.93
A15: =CALCULO!A15 -> 25596 | B15: =IF(CALCULO!D15="","",CALCULO!D15) | C15: =IF(CALCULO!E15="","",CALCULO!E15) | D15: =IF(CALCULO!F15="","",CALCULO!F15) | E15: =IF(CALCULO!G15="","",CALCULO!G15) | G15: =IF(F15="","",ROUND((F15-B15)/B15,4)) | H15: =IF(F15="","",1-IMPOSTOS-CALCULO!B15/F15) | I15: =IF(F15="","",H15-CALCULO!C15) | J15: =IF(F15="","",ROUND(CALCULO!B15/(1-IMPOSTOS-H15-TAXA_3X),2)) | K15: =IF(F15="","",ROUND(CALCULO!B15/(1-IMPOSTOS-H15-TAXA_6X),2)) | L15: =IF(F15="","",ROUND(CALCULO!B15/(1-IMPOSTOS-H15-TAXA_10X),2)) | N15: MARGEM_REAL% é quanto deste valor vem para a empresa com o preço praticado.
A16: =CALCULO!A16 -> 25872 | B16: =IF(CALCULO!D16="","",CALCULO!D16) -> 10427.41 | C16: =IF(CALCULO!E16="","",CALCULO!E16) -> 11583.97 | D16: =IF(CALCULO!F16="","",CALCULO!F16) -> 12211.96 | E16: =IF(CALCULO!G16="","",CALCULO!G16) -> 13828.95 | F16: 6758 | G16: =IF(F16="","",ROUND((F16-B16)/B16,4)) -> -0.3519 | H16: =IF(F16="","",1-IMPOSTOS-CALCULO!B16/F16) -> 0.060711838 | I16: =IF(F16="","",H16-CALCULO!C16) -> -0.23928816 | J16: =IF(F16="","",ROUND(CALCULO!B16/(1-IMPOSTOS-H16-TAXA_3X),2)) -> 7225.54 | K16: =IF(F16="","",ROUND(CALCULO!B16/(1-IMPOSTOS-H16-TAXA_6X),2)) -> 7464.99 | L16: =IF(F16="","",ROUND(CALCULO!B16/(1-IMPOSTOS-H16-TAXA_10X),2)) -> 8039.63
A17: =CALCULO!A17 -> 25871 | B17: =IF(CALCULO!D17="","",CALCULO!D17) | C17: =IF(CALCULO!E17="","",CALCULO!E17) | D17: =IF(CALCULO!F17="","",CALCULO!F17) | E17: =IF(CALCULO!G17="","",CALCULO!G17) | G17: =IF(F17="","",ROUND((F17-B17)/B17,4)) | H17: =IF(F17="","",1-IMPOSTOS-CALCULO!B17/F17) | I17: =IF(F17="","",H17-CALCULO!C17) | J17: =IF(F17="","",ROUND(CALCULO!B17/(1-IMPOSTOS-H17-TAXA_3X),2)) | K17: =IF(F17="","",ROUND(CALCULO!B17/(1-IMPOSTOS-H17-TAXA_6X),2)) | L17: =IF(F17="","",ROUND(CALCULO!B17/(1-IMPOSTOS-H17-TAXA_10X),2))
A18: =CALCULO!A18 -> 25724 | B18: =IF(CALCULO!D18="","",CALCULO!D18) -> 11260.09 | C18: =IF(CALCULO!E18="","",CALCULO!E18) -> 12509 | D18: =IF(CALCULO!F18="","",CALCULO!F18) -> 13187.14 | E18: =IF(CALCULO!G18="","",CALCULO!G18) -> 14933.25 | F18: 7932 | G18: =IF(F18="","",ROUND((F18-B18)/B18,4)) -> -0.2956 | H18: =IF(F18="","",1-IMPOSTOS-CALCULO!B18/F18) -> 0.11509233 | I18: =IF(F18="","",H18-CALCULO!C18) -> -0.18490767 | J18: =IF(F18="","",ROUND(CALCULO!B18/(1-IMPOSTOS-H18-TAXA_3X),2)) -> 8532.07 | K18: =IF(F18="","",ROUND(CALCULO!B18/(1-IMPOSTOS-H18-TAXA_6X),2)) -> 8842.22 | L18: =IF(F18="","",ROUND(CALCULO!B18/(1-IMPOSTOS-H18-TAXA_10X),2)) -> 9594.44 | N18: GAP_MARGEM% representa a diferença percentual abaixo do que era esperado como margem.
A19: =CALCULO!A19 -> 25723 | B19: =IF(CALCULO!D19="","",CALCULO!D19) | C19: =IF(CALCULO!E19="","",CALCULO!E19) | D19: =IF(CALCULO!F19="","",CALCULO!F19) | E19: =IF(CALCULO!G19="","",CALCULO!G19) | G19: =IF(F19="","",ROUND((F19-B19)/B19,4)) | H19: =IF(F19="","",1-IMPOSTOS-CALCULO!B19/F19) | I19: =IF(F19="","",H19-CALCULO!C19) | J19: =IF(F19="","",ROUND(CALCULO!B19/(1-IMPOSTOS-H19-TAXA_3X),2)) | K19: =IF(F19="","",ROUND(CALCULO!B19/(1-IMPOSTOS-H19-TAXA_6X),2)) | L19: =IF(F19="","",ROUND(CALCULO!B19/(1-IMPOSTOS-H19-TAXA_10X),2))
A20: =CALCULO!A20 -> 25928 | B20: =IF(CALCULO!D20="","",CALCULO!D20) -> 15097.98 | C20: =IF(CALCULO!E20="","",CALCULO!E20) -> 16772.57 | D20: =IF(CALCULO!F20="","",CALCULO!F20) -> 17681.85 | E20: =IF(CALCULO!G20="","",CALCULO!G20) -> 20023.11 | F20: 11053 | G20: =IF(F20="","",ROUND((F20-B20)/B20,4)) -> -0.2679 | H20: =IF(F20="","",1-IMPOSTOS-CALCULO!B20/F20) -> 0.13872045 | I20: =IF(F20="","",H20-CALCULO!C20) -> -0.16127955 | J20: =IF(F20="","",ROUND(CALCULO!B20/(1-IMPOSTOS-H20-TAXA_3X),2)) -> 11924.59 | K20: =IF(F20="","",ROUND(CALCULO!B20/(1-IMPOSTOS-H20-TAXA_6X),2)) -> 12377.11 | L20: =IF(F20="","",ROUND(CALCULO!B20/(1-IMPOSTOS-H20-TAXA_10X),2)) -> 13480.46
A21: =CALCULO!A21 -> 25927 | B21: =IF(CALCULO!D21="","",CALCULO!D21) | C21: =IF(CALCULO!E21="","",CALCULO!E21) | D21: =IF(CALCULO!F21="","",CALCULO!F21) | E21: =IF(CALCULO!G21="","",CALCULO!G21) | G21: =IF(F21="","",ROUND((F21-B21)/B21,4)) | H21: =IF(F21="","",1-IMPOSTOS-CALCULO!B21/F21) | I21: =IF(F21="","",H21-CALCULO!C21) | J21: =IF(F21="","",ROUND(CALCULO!B21/(1-IMPOSTOS-H21-TAXA_3X),2)) | K21: =IF(F21="","",ROUND(CALCULO!B21/(1-IMPOSTOS-H21-TAXA_6X),2)) | L21: =IF(F21="","",ROUND(CALCULO!B21/(1-IMPOSTOS-H21-TAXA_10X),2))
A22: =CALCULO!A22 -> 27098 | B22: =IF(CALCULO!D22="","",CALCULO!D22) -> 0 | C22: =IF(CALCULO!E22="","",CALCULO!E22) -> 0 | D22: =IF(CALCULO!F22="","",CALCULO!F22) -> 0 | E22: =IF(CALCULO!G22="","",CALCULO!G22) -> 0 | F22: 9800 | G22: =IF(F22="","",ROUND((F22-B22)/B22,4)) -> #DIV/0! | H22: =IF(F22="","",1-IMPOSTOS-CALCULO!B22/F22) -> 0.7407 | I22: =IF(F22="","",H22-CALCULO!C22) -> 0.4407 | J22: =IF(F22="","",ROUND(CALCULO!B22/(1-IMPOSTOS-H22-TAXA_3X),2)) -> 0 | K22: =IF(F22="","",ROUND(CALCULO!B22/(1-IMPOSTOS-H22-TAXA_6X),2)) -> 0 | L22: =IF(F22="","",ROUND(CALCULO!B22/(1-IMPOSTOS-H22-TAXA_10X),2)) -> 0
A23: =CALCULO!A23 -> 27099 | B23: =IF(CALCULO!D23="","",CALCULO!D23) | C23: =IF(CALCULO!E23="","",CALCULO!E23) | D23: =IF(CALCULO!F23="","",CALCULO!F23) | E23: =IF(CALCULO!G23="","",CALCULO!G23) | G23: =IF(F23="","",ROUND((F23-B23)/B23,4)) | H23: =IF(F23="","",1-IMPOSTOS-CALCULO!B23/F23) | I23: =IF(F23="","",H23-CALCULO!C23) | J23: =IF(F23="","",ROUND(CALCULO!B23/(1-IMPOSTOS-H23-TAXA_3X),2)) | K23: =IF(F23="","",ROUND(CALCULO!B23/(1-IMPOSTOS-H23-TAXA_6X),2)) | L23: =IF(F23="","",ROUND(CALCULO!B23/(1-IMPOSTOS-H23-TAXA_10X),2))
A24: =CALCULO!A24 -> 26882 | B24: =IF(CALCULO!D24="","",CALCULO!D24) -> 0 | C24: =IF(CALCULO!E24="","",CALCULO!E24) -> 0 | D24: =IF(CALCULO!F24="","",CALCULO!F24) -> 0 | E24: =IF(CALCULO!G24="","",CALCULO!G24) -> 0 | F24: 5870 | G24: =IF(F24="","",ROUND((F24-B24)/B24,4)) -> #DIV/0! | H24: =IF(F24="","",1-IMPOSTOS-CALCULO!B24/F24) -> 0.7407 | I24: =IF(F24="","",H24-CALCULO!C24) -> 0.4407 | J24: =IF(F24="","",ROUND(CALCULO!B24/(1-IMPOSTOS-H24-TAXA_3X),2)) -> 0 | K24: =IF(F24="","",ROUND(CALCULO!B24/(1-IMPOSTOS-H24-TAXA_6X),2)) -> 0 | L24: =IF(F24="","",ROUND(CALCULO!B24/(1-IMPOSTOS-H24-TAXA_10X),2)) -> 0
A25: =CALCULO!A25 -> 26881 | B25: =IF(CALCULO!D25="","",CALCULO!D25) | C25: =IF(CALCULO!E25="","",CALCULO!E25) | D25: =IF(CALCULO!F25="","",CALCULO!F25) | E25: =IF(CALCULO!G25="","",CALCULO!G25) | G25: =IF(F25="","",ROUND((F25-B25)/B25,4)) | H25: =IF(F25="","",1-IMPOSTOS-CALCULO!B25/F25) | I25: =IF(F25="","",H25-CALCULO!C25) | J25: =IF(F25="","",ROUND(CALCULO!B25/(1-IMPOSTOS-H25-TAXA_3X),2)) | K25: =IF(F25="","",ROUND(CALCULO!B25/(1-IMPOSTOS-H25-TAXA_6X),2)) | L25: =IF(F25="","",ROUND(CALCULO!B25/(1-IMPOSTOS-H25-TAXA_10X),2))
A26: =CALCULO!A26 -> 26834 | B26: =IF(CALCULO!D26="","",CALCULO!D26) | C26: =IF(CALCULO!E26="","",CALCULO!E26) | D26: =IF(CALCULO!F26="","",CALCULO!F26) | E26: =IF(CALCULO!G26="","",CALCULO!G26) | G26: =IF(F26="","",ROUND((F26-B26)/B26,4)) | H26: =IF(F26="","",1-IMPOSTOS-CALCULO!B26/F26) | I26: =IF(F26="","",H26-CALCULO!C26) | J26: =IF(F26="","",ROUND(CALCULO!B26/(1-IMPOSTOS-H26-TAXA_3X),2)) | K26: =IF(F26="","",ROUND(CALCULO!B26/(1-IMPOSTOS-H26-TAXA_6X),2)) | L26: =IF(F26="","",ROUND(CALCULO!B26/(1-IMPOSTOS-H26-TAXA_10X),2))
A27: =CALCULO!A27 -> 26890 | B27: =IF(CALCULO!D27="","",CALCULO!D27) -> 0 | C27: =IF(CALCULO!E27="","",CALCULO!E27) -> 0 | D27: =IF(CALCULO!F27="","",CALCULO!F27) -> 0 | E27: =IF(CALCULO!G27="","",CALCULO!G27) -> 0 | F27: 6235 | G27: =IF(F27="","",ROUND((F27-B27)/B27,4)) -> #DIV/0! | H27: =IF(F27="","",1-IMPOSTOS-CALCULO!B27/F27) -> 0.7407 | I27: =IF(F27="","",H27-CALCULO!C27) -> 0.4407 | J27: =IF(F27="","",ROUND(CALCULO!B27/(1-IMPOSTOS-H27-TAXA_3X),2)) -> 0 | K27: =IF(F27="","",ROUND(CALCULO!B27/(1-IMPOSTOS-H27-TAXA_6X),2)) -> 0 | L27: =IF(F27="","",ROUND(CALCULO!B27/(1-IMPOSTOS-H27-TAXA_10X),2)) -> 0
A28: =CALCULO!A28 -> 26891 | B28: =IF(CALCULO!D28="","",CALCULO!D28) | C28: =IF(CALCULO!E28="","",CALCULO!E28) | D28: =IF(CALCULO!F28="","",CALCULO!F28) | E28: =IF(CALCULO!G28="","",CALCULO!G28) | G28: =IF(F28="","",ROUND((F28-B28)/B28,4)) | H28: =IF(F28="","",1-IMPOSTOS-CALCULO!B28/F28) | I28: =IF(F28="","",H28-CALCULO!C28) | J28: =IF(F28="","",ROUND(CALCULO!B28/(1-IMPOSTOS-H28-TAXA_3X),2)) | K28: =IF(F28="","",ROUND(CALCULO!B28/(1-IMPOSTOS-H28-TAXA_6X),2)) | L28: =IF(F28="","",ROUND(CALCULO!B28/(1-IMPOSTOS-H28-TAXA_10X),2))
A29: =CALCULO!A29 -> 26834 | B29: =IF(CALCULO!D29="","",CALCULO!D29) | C29: =IF(CALCULO!E29="","",CALCULO!E29) | D29: =IF(CALCULO!F29="","",CALCULO!F29) | E29: =IF(CALCULO!G29="","",CALCULO!G29) | G29: =IF(F29="","",ROUND((F29-B29)/B29,4)) | H29: =IF(F29="","",1-IMPOSTOS-CALCULO!B29/F29) | I29: =IF(F29="","",H29-CALCULO!C29) | J29: =IF(F29="","",ROUND(CALCULO!B29/(1-IMPOSTOS-H29-TAXA_3X),2)) | K29: =IF(F29="","",ROUND(CALCULO!B29/(1-IMPOSTOS-H29-TAXA_6X),2)) | L29: =IF(F29="","",ROUND(CALCULO!B29/(1-IMPOSTOS-H29-TAXA_10X),2))
A30: =CALCULO!A30 -> 26892 | B30: =IF(CALCULO!D30="","",CALCULO!D30) -> 0 | C30: =IF(CALCULO!E30="","",CALCULO!E30) -> 0 | D30: =IF(CALCULO!F30="","",CALCULO!F30) -> 0 | E30: =IF(CALCULO!G30="","",CALCULO!G30) -> 0 | F30: 7450 | G30: =IF(F30="","",ROUND((F30-B30)/B30,4)) -> #DIV/0! | H30: =IF(F30="","",1-IMPOSTOS-CALCULO!B30/F30) -> 0.7407 | I30: =IF(F30="","",H30-CALCULO!C30) -> 0.4407 | J30: =IF(F30="","",ROUND(CALCULO!B30/(1-IMPOSTOS-H30-TAXA_3X),2)) -> 0 | K30: =IF(F30="","",ROUND(CALCULO!B30/(1-IMPOSTOS-H30-TAXA_6X),2)) -> 0 | L30: =IF(F30="","",ROUND(CALCULO!B30/(1-IMPOSTOS-H30-TAXA_10X),2)) -> 0
A31: =CALCULO!A31 -> 26893 | B31: =IF(CALCULO!D31="","",CALCULO!D31) | C31: =IF(CALCULO!E31="","",CALCULO!E31) | D31: =IF(CALCULO!F31="","",CALCULO!F31) | E31: =IF(CALCULO!G31="","",CALCULO!G31) | G31: =IF(F31="","",ROUND((F31-B31)/B31,4)) | H31: =IF(F31="","",1-IMPOSTOS-CALCULO!B31/F31) | I31: =IF(F31="","",H31-CALCULO!C31) | J31: =IF(F31="","",ROUND(CALCULO!B31/(1-IMPOSTOS-H31-TAXA_3X),2)) | K31: =IF(F31="","",ROUND(CALCULO!B31/(1-IMPOSTOS-H31-TAXA_6X),2)) | L31: =IF(F31="","",ROUND(CALCULO!B31/(1-IMPOSTOS-H31-TAXA_10X),2))
A32: =CALCULO!A32 -> 26834 | B32: =IF(CALCULO!D32="","",CALCULO!D32) | C32: =IF(CALCULO!E32="","",CALCULO!E32) | D32: =IF(CALCULO!F32="","",CALCULO!F32) | E32: =IF(CALCULO!G32="","",CALCULO!G32) | G32: =IF(F32="","",ROUND((F32-B32)/B32,4)) | H32: =IF(F32="","",1-IMPOSTOS-CALCULO!B32/F32) | I32: =IF(F32="","",H32-CALCULO!C32) | J32: =IF(F32="","",ROUND(CALCULO!B32/(1-IMPOSTOS-H32-TAXA_3X),2)) | K32: =IF(F32="","",ROUND(CALCULO!B32/(1-IMPOSTOS-H32-TAXA_6X),2)) | L32: =IF(F32="","",ROUND(CALCULO!B32/(1-IMPOSTOS-H32-TAXA_10X),2))
A33: =CALCULO!A33 -> 25721 | B33: =IF(CALCULO!D33="","",CALCULO!D33) -> 9023.64 | C33: =IF(CALCULO!E33="","",CALCULO!E33) -> 10024.5 | D33: =IF(CALCULO!F33="","",CALCULO!F33) -> 10567.95 | E33: =IF(CALCULO!G33="","",CALCULO!G33) -> 11967.26 | F33: 7123 | G33: =IF(F33="","",ROUND((F33-B33)/B33,4)) -> -0.2106 | H33: =IF(F33="","",1-IMPOSTOS-CALCULO!B33/F33) -> 0.18240715 | I33: =IF(F33="","",H33-CALCULO!C33) -> -0.11759285 | J33: =IF(F33="","",ROUND(CALCULO!B33/(1-IMPOSTOS-H33-TAXA_3X),2)) -> 7732.4 | K33: =IF(F33="","",ROUND(CALCULO!B33/(1-IMPOSTOS-H33-TAXA_6X),2)) -> 8051.79 | L33: =IF(F33="","",ROUND(CALCULO!B33/(1-IMPOSTOS-H33-TAXA_10X),2)) -> 8839.26
A34: =CALCULO!A34 -> 25720 | B34: =IF(CALCULO!D34="","",CALCULO!D34) | C34: =IF(CALCULO!E34="","",CALCULO!E34) | D34: =IF(CALCULO!F34="","",CALCULO!F34) | E34: =IF(CALCULO!G34="","",CALCULO!G34) | G34: =IF(F34="","",ROUND((F34-B34)/B34,4)) | H34: =IF(F34="","",1-IMPOSTOS-CALCULO!B34/F34) | I34: =IF(F34="","",H34-CALCULO!C34) | J34: =IF(F34="","",ROUND(CALCULO!B34/(1-IMPOSTOS-H34-TAXA_3X),2)) | K34: =IF(F34="","",ROUND(CALCULO!B34/(1-IMPOSTOS-H34-TAXA_6X),2)) | L34: =IF(F34="","",ROUND(CALCULO!B34/(1-IMPOSTOS-H34-TAXA_10X),2))
A35: =CALCULO!A35 -> 25722 | B35: =IF(CALCULO!D35="","",CALCULO!D35) | C35: =IF(CALCULO!E35="","",CALCULO!E35) | D35: =IF(CALCULO!F35="","",CALCULO!F35) | E35: =IF(CALCULO!G35="","",CALCULO!G35) | G35: =IF(F35="","",ROUND((F35-B35)/B35,4)) | H35: =IF(F35="","",1-IMPOSTOS-CALCULO!B35/F35) | I35: =IF(F35="","",H35-CALCULO!C35) | J35: =IF(F35="","",ROUND(CALCULO!B35/(1-IMPOSTOS-H35-TAXA_3X),2)) | K35: =IF(F35="","",ROUND(CALCULO!B35/(1-IMPOSTOS-H35-TAXA_6X),2)) | L35: =IF(F35="","",ROUND(CALCULO!B35/(1-IMPOSTOS-H35-TAXA_10X),2))
A36: =CALCULO!A36 -> 25937 | B36: =IF(CALCULO!D36="","",CALCULO!D36) -> 9023.64 | C36: =IF(CALCULO!E36="","",CALCULO!E36) -> 10024.5 | D36: =IF(CALCULO!F36="","",CALCULO!F36) -> 10567.95 | E36: =IF(CALCULO!G36="","",CALCULO!G36) -> 11967.26 | F36: 7123 | G36: =IF(F36="","",ROUND((F36-B36)/B36,4)) -> -0.2106 | H36: =IF(F36="","",1-IMPOSTOS-CALCULO!B36/F36) -> 0.18240715 | I36: =IF(F36="","",H36-CALCULO!C36) -> -0.11759285 | J36: =IF(F36="","",ROUND(CALCULO!B36/(1-IMPOSTOS-H36-TAXA_3X),2)) -> 7732.4 | K36: =IF(F36="","",ROUND(CALCULO!B36/(1-IMPOSTOS-H36-TAXA_6X),2)) -> 8051.79 | L36: =IF(F36="","",ROUND(CALCULO!B36/(1-IMPOSTOS-H36-TAXA_10X),2)) -> 8839.26
A37: =CALCULO!A37 -> 25936 | B37: =IF(CALCULO!D37="","",CALCULO!D37) | C37: =IF(CALCULO!E37="","",CALCULO!E37) | D37: =IF(CALCULO!F37="","",CALCULO!F37) | E37: =IF(CALCULO!G37="","",CALCULO!G37) | G37: =IF(F37="","",ROUND((F37-B37)/B37,4)) | H37: =IF(F37="","",1-IMPOSTOS-CALCULO!B37/F37) | I37: =IF(F37="","",H37-CALCULO!C37) | J37: =IF(F37="","",ROUND(CALCULO!B37/(1-IMPOSTOS-H37-TAXA_3X),2)) | K37: =IF(F37="","",ROUND(CALCULO!B37/(1-IMPOSTOS-H37-TAXA_6X),2)) | L37: =IF(F37="","",ROUND(CALCULO!B37/(1-IMPOSTOS-H37-TAXA_10X),2))
A38: =CALCULO!A38 -> 25938 | B38: =IF(CALCULO!D38="","",CALCULO!D38) | C38: =IF(CALCULO!E38="","",CALCULO!E38) | D38: =IF(CALCULO!F38="","",CALCULO!F38) | E38: =IF(CALCULO!G38="","",CALCULO!G38) | G38: =IF(F38="","",ROUND((F38-B38)/B38,4)) | H38: =IF(F38="","",1-IMPOSTOS-CALCULO!B38/F38) | I38: =IF(F38="","",H38-CALCULO!C38) | J38: =IF(F38="","",ROUND(CALCULO!B38/(1-IMPOSTOS-H38-TAXA_3X),2)) | K38: =IF(F38="","",ROUND(CALCULO!B38/(1-IMPOSTOS-H38-TAXA_6X),2)) | L38: =IF(F38="","",ROUND(CALCULO!B38/(1-IMPOSTOS-H38-TAXA_10X),2))
A39: =CALCULO!A39 -> 25930 | B39: =IF(CALCULO!D39="","",CALCULO!D39) -> 13939.82 | C39: =IF(CALCULO!E39="","",CALCULO!E39) -> 15485.96 | D39: =IF(CALCULO!F39="","",CALCULO!F39) -> 16325.48 | E39: =IF(CALCULO!G39="","",CALCULO!G39) -> 18487.15 | F39: 9730 | G39: =IF(F39="","",ROUND((F39-B39)/B39,4)) -> -0.302 | H39: =IF(F39="","",1-IMPOSTOS-CALCULO!B39/F39) -> 0.10932487 | I39: =IF(F39="","",H39-CALCULO!C39) -> -0.19067513 | J39: =IF(F39="","",ROUND(CALCULO!B39/(1-IMPOSTOS-H39-TAXA_3X),2)) -> 10458.87 | K39: =IF(F39="","",ROUND(CALCULO!B39/(1-IMPOSTOS-H39-TAXA_6X),2)) -> 10835.18 | L39: =IF(F39="","",ROUND(CALCULO!B39/(1-IMPOSTOS-H39-TAXA_10X),2)) -> 11746.79
A40: =CALCULO!A40 -> 25929 | B40: =IF(CALCULO!D40="","",CALCULO!D40) | C40: =IF(CALCULO!E40="","",CALCULO!E40) | D40: =IF(CALCULO!F40="","",CALCULO!F40) | E40: =IF(CALCULO!G40="","",CALCULO!G40) | G40: =IF(F40="","",ROUND((F40-B40)/B40,4)) | H40: =IF(F40="","",1-IMPOSTOS-CALCULO!B40/F40) | I40: =IF(F40="","",H40-CALCULO!C40) | J40: =IF(F40="","",ROUND(CALCULO!B40/(1-IMPOSTOS-H40-TAXA_3X),2)) | K40: =IF(F40="","",ROUND(CALCULO!B40/(1-IMPOSTOS-H40-TAXA_6X),2)) | L40: =IF(F40="","",ROUND(CALCULO!B40/(1-IMPOSTOS-H40-TAXA_10X),2))
...
